<?xml version="1.0" encoding="utf-8"?>

<robot
  name="airbot">
  <link name="base_footprint">
  </link>
  <link
    name="base_link">
    <inertial>
      <origin
        xyz="-0.232585512923986 -0.000202710517102245 0.0754844725185804"
        rpy="0 0 0" />
      <mass
        value="20.4302893769782" />
      <inertia
        ixx="0.10818127191238"
        ixy="0.00117617715904733"
        ixz="0.00195467259153544"
        iyy="0.332275534408787"
        iyz="-2.71507482566009E-05"
        izz="0.353879557301462" />
    </inertial>
    <visual>
      <origin
        xyz="0 0 0"
        rpy="0 0 0" />
      <geometry>
        <mesh
          filename="package://airbot_model/meshes/base_link.STL" />
      </geometry>
      <material
        name="">
        <color
          rgba="0.752941176470588 0.752941176470588 0.752941176470588 1" />
      </material>
    </visual>
    <collision>
      <origin
        xyz="0 0 0"
        rpy="0 0 0" />
      <geometry>
        <mesh
          filename="package://airbot_model/meshes/base_link.STL" />
      </geometry>
    </collision>
  </link>
  <joint name="footprint_joint" type="fixed">
    <origin xyz="0 0 0.1015" rpy="0 0 0" />
    <parent link="base_footprint" />
    <child link="base_link" />
  </joint>
  <link
    name="left_drive_wheel_link">
    <inertial>
      <origin
        xyz="-1.38777878078145E-17 0.000112345846468839 0"
        rpy="0 0 0" />
      <mass
        value="0.718343904251702" />
      <inertia
        ixx="0.00291765297431338"
        ixy="7.91259467091988E-18"
        ixz="3.0696706902252E-19"
        iyy="0.00556961462137573"
        iyz="1.0670850376669E-17"
        izz="0.00291765297431338" />
    </inertial>
    <visual>
      <origin
        xyz="0 0 0"
        rpy="0 0 0" />
      <geometry>
        <mesh
          filename="package://airbot_model/meshes/left_drive_wheel_link.STL" />
      </geometry>
      <material
        name="">
        <color
          rgba="0.792156862745098 0.819607843137255 0.933333333333333 1" />
      </material>
    </visual>
    <collision>
      <origin
        xyz="0 0 0"
        rpy="0 0 0" />
      <geometry>
        <mesh
          filename="package://airbot_model/meshes/left_drive_wheel_link.STL" />
      </geometry>
    </collision>
  </link>
  <joint
    name="left_drive_wheel_joint"
    type="continuous">
    <origin
      xyz="0 0.17765 0"
      rpy="0 0 0" />
    <parent
      link="base_link" />
    <child
      link="left_drive_wheel_link" />
    <axis
      xyz="0 1 0" />
  </joint>
  <link
    name="right_drive_wheel_link">
    <inertial>
      <origin
        xyz="6.93889390390723E-18 -0.000112345846468853 0"
        rpy="0 0 0" />
      <mass
        value="0.718343904251704" />
      <inertia
        ixx="0.00291765297431338"
        ixy="1.13140136994246E-17"
        ixz="-1.35161685061559E-19"
        iyy="0.00556961462137574"
        iyz="4.77111730885371E-18"
        izz="0.00291765297431338" />
    </inertial>
    <visual>
      <origin
        xyz="0 0 0"
        rpy="0 0 0" />
      <geometry>
        <mesh
          filename="package://airbot_model/meshes/right_drive_wheel_link.STL" />
      </geometry>
      <material
        name="">
        <color
          rgba="0.792156862745098 0.819607843137255 0.933333333333333 1" />
      </material>
    </visual>
    <collision>
      <origin
        xyz="0 0 0"
        rpy="0 0 0" />
      <geometry>
        <mesh
          filename="package://airbot_model/meshes/right_drive_wheel_link.STL" />
      </geometry>
    </collision>
  </link>
  <joint
    name="right_drive_wheel_joint"
    type="continuous">
    <origin
      xyz="0 -0.17765 0"
      rpy="0 0 0" />
    <parent
      link="base_link" />
    <child
      link="right_drive_wheel_link" />
    <axis
      xyz="0 1 0" />
  </joint>
  <link
    name="left_castor_link">
    <inertial>
      <origin
        xyz="0.0344837361112976 0.000472043535117136 -0.0628091468120086"
        rpy="0 0 0" />
      <mass
        value="0.266935260869721" />
      <inertia
        ixx="0.00019503804714236"
        ixy="5.83606912055227E-08"
        ixz="9.66598777415993E-06"
        iyy="0.000333766619227523"
        iyz="-1.58834315406199E-07"
        izz="0.000187556425299617" />
    </inertial>
    <visual>
      <origin
        xyz="0 0 0"
        rpy="0 0 0" />
      <geometry>
        <mesh
          filename="package://airbot_model/meshes/left_castor_link.STL" />
      </geometry>
      <material
        name="">
        <color
          rgba="0.749019607843137 0.749019607843137 0.749019607843137 1" />
      </material>
    </visual>
    <collision>
      <origin
        xyz="0 0 0"
        rpy="0 0 0" />
      <geometry>
        <mesh
          filename="package://airbot_model/meshes/left_castor_link.STL" />
      </geometry>
    </collision>
  </link>
  <joint
    name="left_castor_joint"
    type="fixed">
    <origin
      xyz="-0.49652 0.15865 0.01915"
      rpy="0 0 0" />
    <parent
      link="base_link" />
    <child
      link="left_castor_link" />
    <axis
      xyz="0 0 0" />
  </joint>
  <link
    name="right_castor_link">
    <inertial>
      <origin
        xyz="0.0344837361112923 0.000472043535117872 -0.0628091468120093"
        rpy="0 0 0" />
      <mass
        value="0.26693526086972" />
      <inertia
        ixx="0.00019503804714236"
        ixy="5.8360691205707E-08"
        ixz="9.66598777416008E-06"
        iyy="0.000333766619227524"
        iyz="-1.58834315406764E-07"
        izz="0.000187556425299617" />
    </inertial>
    <visual>
      <origin
        xyz="0 0 0"
        rpy="0 0 0" />
      <geometry>
        <mesh
          filename="package://airbot_model/meshes/right_castor_link.STL" />
      </geometry>
      <material
        name="">
        <color
          rgba="0.749019607843137 0.749019607843137 0.749019607843137 1" />
      </material>
    </visual>
    <collision>
      <origin
        xyz="0 0 0"
        rpy="0 0 0" />
      <geometry>
        <mesh
          filename="package://airbot_model/meshes/right_castor_link.STL" />
      </geometry>
    </collision>
  </link>
  <joint
    name="right_castor_joint"
    type="fixed">
    <origin
      xyz="-0.49652 -0.15865 0.01915"
      rpy="0 0 0" />
    <parent
      link="base_link" />
    <child
      link="right_castor_link" />
    <axis
      xyz="0 0 0" />
  </joint>
  <link
    name="front_left_sensor_link">
    <inertial>
      <origin
        xyz="0.00553999948389383 -0.002474531719505 -0.000506515757655229"
        rpy="0 0 0" />
      <mass
        value="0.00594142142855535" />
      <inertia
        ixx="6.97108189249103E-07"
        ixy="6.54250251176302E-09"
        ixz="1.33919504472529E-09"
        iyy="2.19037932130412E-07"
        iyz="1.56432353864297E-09"
        izz="6.90071283354614E-07" />
    </inertial>
    <visual>
      <origin
        xyz="0 0 0"
        rpy="0 0 0" />
      <geometry>
        <mesh
          filename="package://airbot_model/meshes/front_left_sensor_link.STL" />
      </geometry>
      <material
        name="">
        <color
          rgba="0.792156862745098 0.819607843137255 0.933333333333333 1" />
      </material>
    </visual>
    <collision>
      <origin
        xyz="0 0 0"
        rpy="0 0 0" />
      <geometry>
        <mesh
          filename="package://airbot_model/meshes/front_left_sensor_link.STL" />
      </geometry>
    </collision>
  </link>
  <joint
    name="front_left_sensor_joint"
    type="fixed">
    <origin
      xyz="0.1152 0.087632 0.074226"
      rpy="0 0 0" />
    <parent
      link="base_link" />
    <child
      link="front_left_sensor_link" />
    <axis
      xyz="0 0 0" />
  </joint>
  <link
    name="front_right_sensor_link">
    <inertial>
      <origin
        xyz="0.00554 0.0024745 0.00050652"
        rpy="0 0 0" />
      <mass
        value="0.0059414" />
      <inertia
        ixx="6.9711E-07"
        ixy="-6.5425E-09"
        ixz="-1.3392E-09"
        iyy="2.1904E-07"
        iyz="1.5643E-09"
        izz="6.9007E-07" />
    </inertial>
    <visual>
      <origin
        xyz="0 0 0"
        rpy="0 0 0" />
      <geometry>
        <mesh
          filename="package://airbot_model/meshes/front_right_sensor_link.STL" />
      </geometry>
      <material
        name="">
        <color
          rgba="0.79216 0.81961 0.93333 1" />
      </material>
    </visual>
    <collision>
      <origin
        xyz="0 0 0"
        rpy="0 0 0" />
      <geometry>
        <mesh
          filename="package://airbot_model/meshes/front_right_sensor_link.STL" />
      </geometry>
    </collision>
  </link>
  <joint
    name="front_right_sensor_joint"
    type="fixed">
    <origin
      xyz="0.1152 -0.084832 0.073668"
      rpy="0 0 0" />
    <parent
      link="base_link" />
    <child
      link="front_right_sensor_link" />
    <axis
      xyz="0 0 0" />
  </joint>
  <link
    name="rear_left_sensor_link">
    <inertial>
      <origin
        xyz="0.00553999948389305 0.00247453171950505 0.000506515757662362"
        rpy="0 0 0" />
      <mass
        value="0.00594142142855535" />
      <inertia
        ixx="6.97108189249106E-07"
        ixy="-6.54250251176159E-09"
        ixz="-1.33919504471636E-09"
        iyy="2.19037932130412E-07"
        iyz="1.56432353863664E-09"
        izz="6.90071283354611E-07" />
    </inertial>
    <visual>
      <origin
        xyz="0 0 0"
        rpy="0 0 0" />
      <geometry>
        <mesh
          filename="package://airbot_model/meshes/rear_left_sensor_link.STL" />
      </geometry>
      <material
        name="">
        <color
          rgba="0.792156862745098 0.819607843137255 0.933333333333333 1" />
      </material>
    </visual>
    <collision>
      <origin
        xyz="0 0 0"
        rpy="0 0 0" />
      <geometry>
        <mesh
          filename="package://airbot_model/meshes/rear_left_sensor_link.STL" />
      </geometry>
    </collision>
  </link>
  <joint
    name="rear_left_sensor_link"
    type="fixed">
    <origin
      xyz="-0.527988612787527 0.0862318443000337 0.0734211663958397"
      rpy="0 0 3.14159265358979" />
    <parent
      link="base_link" />
    <child
      link="rear_left_sensor_link" />
    <axis
      xyz="0 0 0" />
  </joint>
  <link
    name="rear_right_sensor_link">
    <inertial>
      <origin
        xyz="0.00553999948389317 -0.00247453171950504 -0.000506515757662501"
        rpy="0 0 0" />
      <mass
        value="0.00594142142855535" />
      <inertia
        ixx="6.97108189249107E-07"
        ixy="6.54250251176213E-09"
        ixz="1.33919504471599E-09"
        iyy="2.19037932130412E-07"
        iyz="1.5643235386367E-09"
        izz="6.90071283354611E-07" />
    </inertial>
    <visual>
      <origin
        xyz="0 0 0"
        rpy="0 0 0" />
      <geometry>
        <mesh
          filename="package://airbot_model/meshes/rear_right_sensor_link.STL" />
      </geometry>
      <material
        name="">
        <color
          rgba="0.792156862745098 0.819607843137255 0.933333333333333 1" />
      </material>
    </visual>
    <collision>
      <origin
        xyz="0 0 0"
        rpy="0 0 0" />
      <geometry>
        <mesh
          filename="package://airbot_model/meshes/rear_right_sensor_link.STL" />
      </geometry>
    </collision>
  </link>
  <joint
    name="rear_right_sensor_joint"
    type="fixed">
    <origin
      xyz="-0.527988612787527 -0.0862318443000334 0.0739788336041575"
      rpy="0 0 3.14159265358979" />
    <parent
      link="base_link" />
    <child
      link="rear_right_sensor_link" />
    <axis
      xyz="0 0 0" />
  </joint>
  <link
    name="top_panel_link">
    <inertial>
      <origin
        xyz="-0.031967 0.0030877 0.37877"
        rpy="0 0 0" />
      <mass
        value="12.324" />
      <inertia
        ixx="0.20868"
        ixy="7.4473E-05"
        ixz="-0.00018908"
        iyy="0.22216"
        iyz="-4.1055E-05"
        izz="0.059643" />
    </inertial>
    <visual>
      <origin
        xyz="0 0 0"
        rpy="0 0 0" />
      <geometry>
        <mesh
          filename="package://airbot_model/meshes/top_panel_link.STL" />
      </geometry>
      <material
        name="">
        <color
          rgba="0.75294 0.75294 0.75294 1" />
      </material>
    </visual>
    <collision>
      <origin
        xyz="0 0 0"
        rpy="0 0 0" />
      <geometry>
        <mesh
          filename="package://airbot_model/meshes/top_panel_link.STL" />
      </geometry>
    </collision>
  </link>
  <joint
    name="top_panel_joint"
    type="fixed">
    <origin
      xyz="-0.19988 0 0.19165"
      rpy="0 0 0" />
    <parent
      link="base_link" />
    <child
      link="top_panel_link" />
    <axis
      xyz="0 0 0" />
  </joint>
  <link
    name="head_link">
    <inertial>
      <origin
        xyz="0.14219 -9.6368E-06 -0.043502"
        rpy="0 0 0" />
      <mass
        value="1.7595" />
      <inertia
        ixx="0.012249"
        ixy="1.0939E-05"
        ixz="1.1182E-06"
        iyy="0.01351"
        iyz="-1.3026E-05"
        izz="0.014085" />
    </inertial>
    <visual>
      <origin
        xyz="0 0 0"
        rpy="0 0 0" />
      <geometry>
        <mesh
          filename="package://airbot_model/meshes/head_link.STL" />
      </geometry>
      <material
        name="">
        <color
          rgba="0.75294 0.75294 0.75294 1" />
      </material>
    </visual>
    <collision>
      <origin
        xyz="0 0 0"
        rpy="0 0 0" />
      <geometry>
        <mesh
          filename="package://airbot_model/meshes/head_link.STL" />
      </geometry>
    </collision>
  </link>
  <joint
    name="head_joint"
    type="continuous">
    <origin
      xyz="-0.17309 0 0.94409"
      rpy="0 0 0" />
    <parent
      link="top_panel_link" />
    <child
      link="head_link" />
    <axis
      xyz="1 0 0" />
  </joint>
  <link
    name="left_lamp_link">
    <inertial>
      <origin
        xyz="-3.6542E-05 0.0011026 -0.00093198"
        rpy="0 0 0" />
      <mass
        value="0.0096192" />
      <inertia
        ixx="6.3204E-05"
        ixy="-4.509E-09"
        ixz="2.9924E-08"
        iyy="6.1722E-05"
        iyz="-1.139E-07"
        izz="1.6639E-06" />
    </inertial>
    <visual>
      <origin
        xyz="0 0 0"
        rpy="0 0 0" />
      <geometry>
        <mesh
          filename="package://airbot_model/meshes/left_lamp_link.STL" />
      </geometry>
      <material
        name="">
        <color
          rgba="0.79216 0.81961 0.93333 1" />
      </material>
    </visual>
    <collision>
      <origin
        xyz="0 0 0"
        rpy="0 0 0" />
      <geometry>
        <mesh
          filename="package://airbot_model/meshes/left_lamp_link.STL" />
      </geometry>
    </collision>
  </link>
  <joint
    name="left_lamp_joint"
    type="fixed">
    <origin
      xyz="0.1526 0.074634 -0.03015"
      rpy="1.5708 0 1.5708" />
    <parent
      link="head_link" />
    <child
      link="left_lamp_link" />
    <axis
      xyz="0 0 0" />
  </joint>
  <link
    name="right_lamp_link">
    <inertial>
      <origin
        xyz="-3.6542E-05 -0.00093577 -0.00093198"
        rpy="0 0 0" />
      <mass
        value="0.0096192" />
      <inertia
        ixx="6.3204E-05"
        ixy="-4.509E-09"
        ixz="2.9924E-08"
        iyy="6.1722E-05"
        iyz="-1.139E-07"
        izz="1.6639E-06" />
    </inertial>
    <visual>
      <origin
        xyz="0 0 0"
        rpy="0 0 0" />
      <geometry>
        <mesh
          filename="package://airbot_model/meshes/right_lamp_link.STL" />
      </geometry>
      <material
        name="">
        <color
          rgba="0.79216 0.81961 0.93333 1" />
      </material>
    </visual>
    <collision>
      <origin
        xyz="0 0 0"
        rpy="0 0 0" />
      <geometry>
        <mesh
          filename="package://airbot_model/meshes/right_lamp_link.STL" />
      </geometry>
    </collision>
  </link>
  <joint
    name="right_lamp_joint"
    type="fixed">
    <origin
      xyz="0.1526 -0.074634 -0.03015"
      rpy="-1.5708 0 -1.5708" />
    <parent
      link="head_link" />
    <child
      link="right_lamp_link" />
    <axis
      xyz="0 0 0" />
  </joint>
  <link
    name="top_lamp_link">
    <inertial>
      <origin
        xyz="-3.6542E-05 8.3428E-05 -0.00093198"
        rpy="0 0 0" />
      <mass
        value="0.0096192" />
      <inertia
        ixx="6.3204E-05"
        ixy="-4.509E-09"
        ixz="2.9924E-08"
        iyy="6.1722E-05"
        iyz="-1.139E-07"
        izz="1.6639E-06" />
    </inertial>
    <visual>
      <origin
        xyz="0 0 0"
        rpy="0 0 0" />
      <geometry>
        <mesh
          filename="package://airbot_model/meshes/top_lamp_link.STL" />
      </geometry>
      <material
        name="">
        <color
          rgba="0.79216 0.81961 0.93333 1" />
      </material>
    </visual>
    <collision>
      <origin
        xyz="0 0 0"
        rpy="0 0 0" />
      <geometry>
        <mesh
          filename="package://airbot_model/meshes/top_lamp_link.STL" />
      </geometry>
    </collision>
  </link>
  <joint
    name="top_lamp_joint"
    type="fixed">
    <origin
      xyz="0.1526 0 0.095949"
      rpy="3.1415926535897931 -1.5708 0" />
    <parent
      link="head_link" />
    <child
      link="top_lamp_link" />
    <axis
      xyz="0 0 0" />
  </joint>

  <!-- Cameras are added using the plugins in Xacro file  -->
  <!-- <link
    name="front_camera_link">
    <inertial>
      <origin
        xyz="-0.013172 -0.0016821 -2.5489E-06"
        rpy="0 0 0" />
      <mass
        value="0.038191" />
      <inertia
        ixx="2.3574E-05"
        ixy="-4.5204E-08"
        ixz="1.3018E-08"
        iyy="2.1119E-06"
        iyz="-7.8613E-09"
        izz="2.2257E-05" />
    </inertial>
    <visual>
      <origin
        xyz="0 0 0"
        rpy="0 0 0" />
      <geometry>
        <mesh
          filename="package://airbot_model/meshes/front_camera_link.STL" />
      </geometry>
      <material
        name="">
        <color
          rgba="0.75294 0.75294 0.75294 1" />
      </material>
    </visual>
    <collision>
      <origin
        xyz="0 0 0"
        rpy="0 0 0" />
      <geometry>
        <mesh
          filename="package://airbot_model/meshes/front_camera_link.STL" />
      </geometry>
    </collision>
  </link>
  <joint
    name="front_camera_joint"
    type="fixed">
    <origin
      xyz="0.1222 0 0.20424"
      rpy="0 0 0" />
    <parent
      link="base_link" />
    <child
      link="front_camera_link" />
    <axis
      xyz="0 0 0" />
  </joint>
  <link
    name="rear_camera_link">
    <inertial>
      <origin
        xyz="-0.0131722081199356 -0.00168214227279699 -2.54857060852376E-06"
        rpy="0 0 0" />
      <mass
        value="0.0381914678127728" />
      <inertia
        ixx="2.35735738625756E-05"
        ixy="-4.52038513328379E-08"
        ixz="1.3018113493093E-08"
        iyy="2.11190886814241E-06"
        iyz="-7.86094501100049E-09"
        izz="2.2256752989384E-05" />
    </inertial>
    <visual>
      <origin
        xyz="0 0 0"
        rpy="0 0 0" />
      <geometry>
        <mesh
          filename="package://airbot_model/meshes/rear_camera_link.STL" />
      </geometry>
      <material
        name="">
        <color
          rgba="0.752941176470588 0.752941176470588 0.752941176470588 1" />
      </material>
    </visual>
    <collision>
      <origin
        xyz="0 0 0"
        rpy="0 0 0" />
      <geometry>
        <mesh
          filename="package://airbot_model/meshes/rear_camera_link.STL" />
      </geometry>
    </collision>
  </link>
  <joint
    name="rear_camera_joint"
    type="fixed">
    <origin
      xyz="-0.5422 0 0.20424"
      rpy="0 0 3.1416" />
    <parent
      link="base_link" />
    <child
      link="rear_camera_link" />
    <axis
      xyz="0 0 0" />
  </joint> -->

</robot>
