<?xml version="1.0" encoding="utf-8"?>
<robot name="core_0">
<link name="base_footprint">
</link>

<joint name="base_joint" type="fixed">
	<origin xyz="0 0 0.075" rpy="0 0 0" />
	<parent link="base_footprint" />
	<child link="base_link" />
</joint>
<!-- BASE LINK -->
<link name="base_link">
	<inertial>
		<origin	xyz="-0.0025703 -0.0004322 0.12876" rpy="0 0 0" />
		<mass value="35" />
		<inertia
  	      		ixx="0.15251"
  	      		ixy="3.3885E-07"
  	     		ixz="-0.00012431"
  	      		iyy="0.15365"
  	      		iyz="1.4955E-07"
  	      		izz="0.24996" />
	</inertial>
	<visual>
		<origin xyz="0 0 0" rpy="0 0 0" />
			<geometry>
  	  			<mesh filename="package://core_0/meshes/base_link.STL" />
			</geometry>
		<material name="">
			<color rgba="0.79216 0.81961 0.93333 1" />
		</material>
	</visual>
	<collision>	
		<origin xyz="0 0 0" rpy="0 0 0" />
      		<geometry>
      			<mesh filename="package://core_0/meshes/base_link.STL" />
      		</geometry>
	</collision>
</link>

<!-- LEFT WHEEL-->
<link	name="wheel_left_link">
	<inertial>
	<origin xyz="-8.2233E-06 0.00016299 7.3949E-06" rpy="0 0 0" />
  	<mass value="1.7" />
   	<inertia
        ixx="0.0050575"
        ixy="3.0166E-10"
        ixz="-1.7358E-07"
        iyy="0.0097294"
        iyz="-2.7127E-10"
        izz="0.0050574" />
	</inertial>
	<visual>
		<origin xyz="0 0 0" rpy="0 0 0" />
		<geometry>
			<mesh filename="package://core_0/meshes/wheel_left_link.STL" />
		</geometry>
		<material name="">
			<color rgba="0.19216 0.20392 0.20392 1" />
		</material>
	</visual>
  	<collision>
	 	<origin xyz="0 0 0" rpy="0 0 0" />
    		<geometry>
     			<mesh filename="package://core_0/meshes/wheel_left_link.STL" />
  		</geometry>
	</collision>
</link>

<joint name="wheel_left_joint" type="continuous">
	<origin xyz="0 0.1823 0" rpy="0 0 0" />
	<parent link="base_link" />
  	<child link="wheel_left_link" />
 	<axis xyz="0 1 0" />
 	<safety_controller k_velocity="0" />
</joint>

<!-- RIGHT WHEEL -->  
<link name="wheel_right_link">
	<inertial>
    	<origin xyz="8.2233E-06 -0.00016299 -7.3949E-06" rpy="0 0 0" />
    	<mass value="1.7" />
      	<inertia
        	ixx="0.0050575"
        	ixy="3.0166E-10"
        	ixz="-1.7358E-07"
        	iyy="0.0097294"
        	iyz="-2.7127E-10"
        	izz="0.0050574" />
	</inertial>
    <visual>
    		<origin xyz="0 0 0" rpy="0 0 0" />
    		<geometry>
        		<mesh filename="package://core_0/meshes/wheel_right_link.STL" />
      		</geometry>
     		<material name="">
        		<color rgba="0.2 0.2 0.2 1" />
      		</material>
	</visual>
    <collision>
    	<origin xyz="0 0 0" rpy="0 0 0" />
      	<geometry>
        	<mesh filename="package://core_0/meshes/wheel_right_link.STL" />
      	</geometry>
    </collision>
</link>

<joint name="wheel_right_joint" type="continuous">
	<origin xyz="0 -0.1823 0" rpy="0 0 0" />
    <parent link="base_link" />
    <child link="wheel_right_link" />
    <axis xyz="0 1 0" />
    <safety_controller k_velocity="0" />
</joint>
  
<!-- CASTOR FRONT LEFT -->
<link name="castor_fl_link">	
	<inertial>
    	<origin xyz="0.028528 -6.467E-05 -0.041459" rpy="0 0 0" />
      	<mass value="0.21467" />
      	<inertia
        	ixx="0.00010858"
        	ixy="9.7025E-08"
        	ixz="1.2517E-05"
        	iyy="0.00015878"
        	iyz="-3.1107E-08"
        	izz="0.00014037" />
	</inertial>
    <visual>
    	<origin xyz="0 0 0" rpy="0 0 0" />
      	<geometry>
        	<mesh filename="package://core_0/meshes/castor_fl_link.STL" />
      	</geometry>
      	<material name="">
        	<color rgba="0.77647 0.75686 0.73725 1" />
      	</material>
    </visual>
    <collision>
    	<origin xyz="0 0 0" rpy="0 0 0" />
      	<geometry>
        	<mesh filename="package://core_0/meshes/castor_fl_link.STL" />
      	</geometry>
    </collision>
</link>

<joint name="castor_fl_joint" type="fixed">
	<origin xyz="0.243 0.14 0.025" rpy="0 0 0" />
    <parent link="base_link" />
    <child link="castor_fl_link" />
    <axis xyz="0 0 0" />
    <safety_controller k_velocity="0" />
</joint>
  
<!-- CASTOR FRONT RIGHT -->  
<link name="castor_fr_link">	
	<inertial> 
		<origin xyz="0.028528 -6.467E-05 -0.041459" rpy="0 0 0" />
      	<mass value="0.21467" />
      	<inertia
        	ixx="0.00010858"
        	ixy="9.7025E-08"
        	ixz="1.2517E-05"
        	iyy="0.00015878"
        	iyz="-3.1107E-08"
        	izz="0.00014037" />
	</inertial>
    <visual>
    	<origin xyz="0 0 0" rpy="0 0 0" />
      	<geometry>
        	<mesh filename="package://core_0/meshes/castor_fr_link.STL" />
      	</geometry>
      	<material name="">
        	<color rgba="0.79216 0.81961 0.93333 1" />
      	</material>
    </visual>
    <collision>
   		<origin xyz="0 0 0" rpy="0 0 0" />
      	<geometry>
        	<mesh filename="package://core_0/meshes/castor_fr_link.STL" />
      	</geometry>
    </collision>
</link>

<joint name="castor_fr_joint" type="fixed">
	<origin xyz="0.243 -0.14 0.025" rpy="0 0 0" />
    <parent link="base_link" />
    <child link="castor_fr_link" />
    <axis xyz="0 0 0" />
    <safety_controller k_velocity="0" />
</joint>
  
<!-- CASTOR REAR RIGHT -->  
<link name="castor_rr_link">
	<inertial>
    	<origin xyz="-0.028528 6.467E-05 -0.041459" rpy="0 0 0" />
      	<mass value="0.21467" />
      	<inertia
        	ixx="0.00010858"
        	ixy="9.7025E-08"
        	ixz="-1.2517E-05"
        	iyy="0.00015878"
        	iyz="3.1107E-08"
        	izz="0.00014037" />
	</inertial>
    <visual>
   		<origin xyz="0 0 0" rpy="0 0 0" />
   		<geometry>
        	<mesh filename="package://core_0/meshes/castor_rr_link.STL" />
      	</geometry>
      	<material name="">
        	<color rgba="0.77647 0.75686 0.73725 1" />
      	</material>
	</visual>
    <collision>
    	<origin xyz="0 0 0" rpy="0 0 0" />
      	<geometry>
        	<mesh filename="package://core_0/meshes/castor_rr_link.STL" />
      	</geometry>
	</collision>
</link>
  
<joint name="castor_rr_joint" type="fixed">
	<origin xyz="-0.243 -0.14 0.025" rpy="0 0 0" />
    <parent link="base_link" />
    <child link="castor_rr_link" />
    <axis xyz="0 0 0" />
    <safety_controller k_velocity="0" />
</joint>

<!-- CASTOR REAR LEFT -->  
<link name="castor_rl_link">
	<inertial> 
		<origin xyz="-0.028528 6.467E-05 -0.041459" rpy="0 0 0" />
      	<mass value="0.21467" />
      	<inertia
        	ixx="0.00010858"
         	ixy="9.7025E-08"
        	ixz="-1.2517E-05"
        	iyy="0.00015878"
       		iyz="3.1107E-08"
        	izz="0.00014037" />
	</inertial>
    <visual>
    	<origin xyz="0 0 0" rpy="0 0 0" />
      	<geometry>
        	<mesh filename="package://core_0/meshes/castor_rl_link.STL" />
      	</geometry>
     	<material name="">
        	<color rgba="0.77647 0.75686 0.73725 1" />
     	</material>
	</visual>
    <collision>
    	<origin xyz="0 0 0" rpy="0 0 0" />
      	<geometry>
       		<mesh filename="package://core_0/meshes/castor_rl_link.STL" />
      	</geometry>
	</collision>
</link>

<joint name="castor_rl_joint" type="fixed">
	<origin xyz="-0.243 0.14 0.025" rpy="0 0 0" />
    <parent link="base_link" />
    <child link="castor_rl_link" />
    <axis xyz="0 0 0" />
    <safety_controller k_velocity="0" />
</joint>
  
<!-- US 1 -->  
<link name="us_sensor1_link">
	<inertial>
    	<origin xyz="-0.38386 0.07483 0.059858" rpy="0 0 0" />
     	<mass value="0.1" />
      	<inertia
        	ixx="0"
        	ixy="0"
        	ixz="0"
        	iyy="0"
        	iyz="0"
        	izz="0" />
	</inertial>
    <visual>
   		<origin	xyz="0 0 0" rpy="0 0 0" />
      	<geometry>
        	<mesh filename="package://core_0/meshes/us_1_link.STL" />
      	</geometry>
      	<material name="">
        	<color rgba="0.79216 0.81961 0.93333 1" />
      	</material>
    </visual>
    <collision>
    	<origin xyz="0 0 0" rpy="0 0 0" />
      	<geometry>
        	<mesh filename="package://core_0/meshes/us_1_link.STL" />
      	</geometry>
    </collision>
</link>

<joint name="us_sensor1_joint" type="fixed">
	<origin xyz="0.31809 0.21909 0.01005" rpy="0 0 0.7854" />
    <parent link="base_link" />
    <child link="us_sensor1_link" />
    <axis xyz="0 0 0" />
    <safety_controller k_velocity="0" />
</joint>

<!-- US 2 -->
<link name="us_sensor2_link">
	<inertial>
    	<origin	xyz="-0.35425 0.00057588 0.059858" rpy="0 0 0" />
      <mass value="0.1" />
      	<inertia
        	ixx="0"
        	ixy="0"
        	ixz="0"
        	iyy="0"
        	iyz="0"
        	izz="0" />
	</inertial>
    <visual>
   		<origin	xyz="0 0 0" rpy="0 0 0" />
      	<geometry>
        	<mesh filename="package://core_0/meshes/us_2_link.STL" />
      	</geometry>
      	<material name="">
        	<color rgba="0.79216 0.81961 0.93333 1" />
      	</material>
    </visual>
    <collision>
    	<origin xyz="0 0 0" rpy="0 0 0" />
      	<geometry>
        	<mesh filename="package://core_0/meshes/us_2_link.STL" />
      	</geometry>
    </collision>
</link>
  
<joint name="us_sensor2_joint" type="fixed">
	<origin xyz="0.348 0 0.01005" rpy="0 0 0" />
    <parent link="base_link" />
    <child link="us_sensor2_link" />
    <axis xyz="0 0 0" />
    <safety_controller k_velocity="0" />
</joint>

<!-- US 3 -->
<link name="us_sensor3_link">
    <inertial>
 		<origin xyz="-0.38467 -0.074015 0.059858" rpy="0 0 0" />
      	<mass value="0.1" />
      	<inertia
        	ixx="0"
        	ixy="0"
        	ixz="0"
        	iyy="0"
        	iyz="0"
        	izz="0" />
	</inertial>
    <visual>
   		<origin	xyz="0 0 0" rpy="0 0 0" />
      	<geometry>
        	<mesh filename="package://core_0/meshes/us_3_link.STL" />
      	</geometry>
      	<material name="">
        	<color rgba="0.79216 0.81961 0.93333 1" />
      	</material>
    </visual>
    <collision>
    	<origin xyz="0 0 0" rpy="0 0 0" />
      	<geometry>
        	<mesh filename="package://core_0/meshes/us_3_link.STL" />
      	</geometry>
    </collision>
</link>

<joint name="us_sensor3_joint" type="fixed">
	<origin xyz="0.31809 -0.21909 0.01005" rpy="0 0 -0.7854" />
    <parent link="base_link" />
    <child link="us_sensor3_link" />
    <axis xyz="0 0 0" />
    <safety_controller k_velocity="0" />
</joint>
  
<!-- US 4 -->
<link name="us_sensor4_link">
	<inertial> 
		<origin xyz="-0.37429 -0.072727 0.059858" rpy="0 0 0" />
      	<mass value="0.1" />
      	<inertia
        	ixx="0"
        	ixy="0"
        	ixz="0"
        	iyy="0"
        	iyz="0"
        	izz="0" />
	</inertial>
    <visual>
   		<origin	xyz="0 0 0" rpy="0 0 0" />
      	<geometry>
        	<mesh filename="package://core_0/meshes/us_4_link.STL" />
      	</geometry>
      	<material name="">
        	<color rgba="0.79216 0.81961 0.93333 1" />
      	</material>
    </visual>
    <collision>
    	<origin xyz="0 0 0" rpy="0 0 0" />
      	<geometry>
        	<mesh filename="package://core_0/meshes/us_4_link.STL" />
      	</geometry>
    </collision>
</link>

<joint name="us_sensor4_joint" type="fixed">
    <origin xyz="-0.31905 0.2186 0.01005" rpy="0 0 2.341" />
    <parent link="base_link" />
    <child link="us_sensor4_link" />
    <axis xyz="0 0 0" />
    <safety_controller k_velocity="0" />
</joint>

<!-- US 5 -->
<link name="us_sensor5_link">
	<inertial>
   		<origin xyz="-0.37512 0.071925 0.059858" rpy="0 0 0" />
      	<mass value="0.1" />
      	<inertia
        	ixx="0"
        	ixy="0"
        	ixz="0"
        	iyy="0"
        	iyz="0"
        	izz="0" />
	</inertial>
    <visual>
   		<origin	xyz="0 0 0" rpy="0 0 0" />
      	<geometry>
        	<mesh filename="package://core_0/meshes/us_5_link.STL" />
      	</geometry>
      	<material name="">
        	<color rgba="0.79216 0.81961 0.93333 1" />
      	</material>
    </visual>
    <collision>
    	<origin xyz="0 0 0" rpy="0 0 0" />
      	<geometry>
        	<mesh filename="package://core_0/meshes/us_5_link.STL" />
      	</geometry>
    </collision>
</link>
  
<joint name="us_sensor5_joint" type="fixed">
	<origin xyz="-0.31905 -0.2186 0.01005" rpy="0 0 -2.341" />
    <parent link="base_link" />
    <child link="us_sensor5_link" />
    <axis xyz="0 0 0" />
    <safety_controller k_velocity="0" />
</joint>

<!-- RP LIDAR -->
<link name="laser">	
	<inertial>
   		<origin xyz="0 0 0" rpy="0 0 0" />
      	<mass value="0" />
      	<inertia
      		ixx="0"
       		ixy="0"
        	ixz="0"
        	iyy="0"
        	iyz="0"
        	izz="0" />
	</inertial>
    <visual>
 		<origin xyz="0 0 0" rpy="0 0 0" />
      	<geometry>
        	<mesh filename="package://core_0/meshes/lidar_link.STL" />
      	</geometry>
      	<material name="">
        	<color rgba="1 1 1 1" />
      	</material>
    </visual>
    <collision>
   		<origin xyz="0 0 0" rpy="0 0 0" />
      	<geometry>
        	<mesh filename="package://core_0/meshes/lidar_link.STL" />
      	</geometry>
    </collision>
</link>
  
<joint name="laser_joint" type="fixed">
	<origin xyz="0 0 0.1528" rpy="0 0 0" />
    <parent link="base_link" />
    <child link="laser_link" />
    <axis xyz="0 0 0" />
    <safety_controller k_velocity="0" />
</joint>
</robot>
